ExecutionError: An error occurred while calling o421.mkdirs.
: com.databricks.backend.daemon.data.filesystem.ReservedPathException: /Volume is a reserved DBFS path. If you need this to be unblocked, please reach out to Databricks Support.
	at com.databricks.backend.daemon.data.filesystem.MountEntryResolver.createFileSystem(MountEntryResolver.scala:149)
	at com.databricks.backend.daemon.data.client.DBFSOnUCFileSystemResolverImpl.createFileSystemByMountEntryResolver(DBFSOnUCFileSystemResolverImpl.scala:229)

	... 85 more
File <command-265156676446858>, line 1
----> 1 process_saved_views(control_table)
File /databricks/python_shell/dbruntime/dbutils.py:158, in prettify_exception_message.<locals>.f_with_exception_handling(*args, **kwargs)
    156 exc.__context__ = None
    157 exc.__cause__ = None
--> 158 raise exc
